Workbook
Name Slicer_carrier_name: #N/A
Name Slicer_cost_per_mile: #N/A
Name Slicer_customer_name: #N/A
Name Slicer_deadhead_miles: #N/A
Name Slicer_driver_pay_total: #N/A
Name Slicer_empty_miles: #N/A
Name Slicer_truck_types: #N/A
Name Slicer_variable_cost_per_mile: #N/A
Name Slicer_Years__scheduled_delivery_datetime: #N/A

Sheet dim_fleet_260
A1: truck_id | B1: driver_id | C1: carrier_id | D1: carrier_name | E1: truck_type | F1: truck_model_year | G1: home_terminal_state | H1: home_terminal_city | I1: insurance_policy_id | J1: insurance_coverage_limit_usd | K1: insurance_deductible_usd | L1: insurance_premium_monthly_usd | M1: insurance_claims_12m | N1: safety_score | O1: maintenance_interval_days | P1: last_maintenance_date | Q1: next_maintenance_due | R1: maintenance_overdue_flag | S1: epr_compliant_flag | T1: epr_audit_score | U1: hazmat_certified_flag
A2: 770487 | B2: 9683481 | C2: 8270 | D2: Desert Road Haulers | E2: Tanker | F2: 2024 | G2: WA | H2: Grand Rapids | I2: 26784725 | J2: 1000000 | K2: 2500 | L2: 1909.09 | M2: 0 | N2: 80 | O2: 45 | P2: 45769 | Q2: 45814 | R2: 0 | S2: 0 | T2: 73.7 | U2: 0
A3: 216739 | B3: 8574680 | C3: 1860 | D3: Pacific Linehaul | E3: Intermodal | F3: 2021 | G3: TX | H3: El Paso | I3: 24081983 | J3: 2000000 | K3: 5000 | L3: 1656.09 | M3: 0 | N3: 76.1 | O3: 45 | P3: 45768 | Q3: 45813 | R3: 0 | S3: 1 | T3: 97.1 | U3: 0
A4: 126225 | B4: 3030113 | C4: 6390 | D4: Midwest Express Trucking | E4: Dry Van | F4: 2011 | G4: WA | H4: Everett | I4: 25137284 | J4: 3000000 | K4: 1000 | L4: 1538.42 | M4: 0 | N4: 83.5 | O4: 30 | P4: 45742 | Q4: 45772 | R4: 0 | S4: 1 | T4: 83 | U4: 0
A5: 877572 | B5: 5159166 | C5: 6191 | D5: Great Lakes Carriers | E5: Reefer | F5: 2025 | G5: TN | H5: Knoxville | I5: 29756883 | J5: 1000000 | K5: 1000 | L5: 1866.24 | M5: 0 | N5: 86 | O5: 45 | P5: 45658 | Q5: 45703 | R5: 0 | S5: 0 | T5: 78.2 | U5: 0
A6: 388389 | B6: 4769795 | C6: 6734 | D6: Pacific Linehaul | E6: Dry Van | F6: 2021 | G6: MI | H6: Flint | I6: 26191135 | J6: 2000000 | K6: 1000 | L6: 1638.04 | M6: 1 | N6: 68.2 | O6: 45 | P6: 45924 | Q6: 45969 | R6: 0 | S6: 1 | T6: 86.6 | U6: 0
A7: 356787 | B7: 2074176 | C7: 7265 | D7: Great Lakes Carriers | E7: Dry Van | F7: 2016 | G7: NC | H7: Durham | I7: 27939993 | J7: 1000000 | K7: 5000 | L7: 1871.91 | M7: 2 | N7: 86.7 | O7: 30 | P7: 46010 | Q7: 46040 | R7: 0 | S7: 1 | T7: 87.6 | U7: 0
A8: 334053 | B8: 6672134 | C8: 1466 | D8: Keystone Freight | E8: Dry Van | F8: 2012 | G8: NJ | H8: Trenton | I8: 29285735 | J8: 1000000 | K8: 2500 | L8: 1442.49 | M8: 1 | N8: 77.1 | O8: 60 | P8: 45739 | Q8: 45799 | R8: 0 | S8: 1 | T8: 88.6 | U8: 0
A9: 246316 | B9: 1352896 | C9: 5426 | D9: Lone Star Transport | E9: Dry Van | F9: 2023 | G9: WA | H9: Tacoma | I9: 28907391 | J9: 3000000 | K9: 2500 | L9: 1566.51 | M9: 1 | N9: 78.2 | O9: 45 | P9: 45900 | Q9: 45945 | R9: 0 | S9: 1 | T9: 89.8 | U9: 0
A10: 872246 | B10: 4860684 | C10: 6578 | D10: Keystone Freight | E10: Reefer | F10: 2021 | G10: AZ | H10: Flagstaff | I10: 25767292 | J10: 2000000 | K10: 5000 | L10: 2355.31 | M10: 2 | N10: 80.4 | O10: 60 | P10: 45928 | Q10: 45988 | R10: 0 | S10: 1 | T10: 87.2 | U10: 0
A11: 207473 | B11: 4694634 | C11: 9322 | D11: Blue Ridge Logistics | E11: Dry Van | F11: 2019 | G11: NJ | H11: Trenton | I11: 27138769 | J11: 2000000 | K11: 5000 | L11: 1479.49 | M11: 1 | N11: 80.1 | O11: 60 | P11: 45967 | Q11: 46027 | R11: 0 | S11: 1 | T11: 89.5 | U11: 0
A12: 809570 | B12: 1120642 | C12: 2685 | D12: Pacific Linehaul | E12: Tanker | F12: 2024 | G12: MI | H12: Grand Rapids | I12: 29233986 | J12: 3000000 | K12: 2500 | L12: 2235.23 | M12: 0 | N12: 90.6 | O12: 30 | P12: 45812 | Q12: 45842 | R12: 0 | S12: 0 | T12: 84 | U12: 0
A13: 876646 | B13: 2191066 | C13: 1769 | D13: Blue Ridge Logistics | E13: Tanker | F13: 2023 | G13: MO | H13: St. Louis | I13: 25549757 | J13: 3000000 | K13: 5000 | L13: 2037.21 | M13: 0 | N13: 84.6 | O13: 60 | P13: 45768 | Q13: 45828 | R13: 0 | S13: 0 | T13: 79.9 | U13: 0
... A261: 559381 | B261: 4526280 | C261: 9754 | D261: Keystone Freight | E261: Reefer | F261: 2024 | G261: AZ | H261: Tucson | I261: 23918527 | J261: 1000000 | K261: 1000 | L261: 2089.22 | M261: 1 | N261: 83.4 | O261: 45 | P261: 45696 | Q261: 45741 | R261: 0 | S261: 1 | T261: 84.5 | U261: 0

Sheet fact_orders_1000
A1: order_id | B1: truck_id | C1: driver_id | D1: carrier_id | E1: carrier_name | F1: customer_id | G1: customer_name | H1: shipping_dat | I1: ship_date_clean | J1: pickup_datetime | K1: scheduled_delivery_datetime | L1: actual_delivery_datetime | M1: delivery_date | N1: origin_state | O1: origin_city | P1: destination_state | Q1: destination_city | R1: region | S1: lane_id | T1: lanes_usa | U1: distance_miles | V1: empty_miles | W1: deadhead_miles | X1: loaded_miles | Y1: total_miles | Z1: truck_types | AA1: delivery_times | AB1: pickup_time_bucket | AC1: day_of_the_week | AD1: Delay Reason | AE1: delay_minutes | AF1: detention_minutes | AG1: weather_severity_index | AH1: traffic_index | AI1: mechanical_flag | AJ1: utilization_rate | AK1: load_factor | AL1: shipment_value_usd | AM1: shipment_value_bucket | AN1: total_shipments | AO1: on_time_deliveries | AP1: late_deliveries | AQ1: on_time_count | AR1: Late_count | AS1: on_time_flag | AT1: late_flag | AU1: cost_per_mile | AV1: variable_cost_per_mile | AW1: fuel_cost_total | AX1: maintenance_cost_total | AY1: driver_pay_total | AZ1: insurance_risk_score | BA1: maintenance_risk_score
A2: 545478870 | B2: 220116 | C2: 6933742 | D2: 5218 | E2: Sunbelt Haulage | F2: 52666 | G2: Coca-Cola Bottling | H2: 45818 | I2: 45818 | J2: 45818.76 | K2: 45818.949 | L2: 45818.93 | M2: 45818 | N2: OH | O2: Toledo | P2: OH | Q2: Cleveland | R2: Midwest | S2: 797593 | T2: 101-300 | U2: 224 | V2: 9.3 | W2: 20.3 | X2: 218.4 | Y2: 248 | Z2: Dry Van | AA2: 4.07 | AB2: 18:00-23:59 | AC2: Tuesday | AE2: -27 | AF2: 0 | AG2: 0 | AH2: 30.2 | AI2: 0 | AJ2: 0.805 | AK2: 0.576 | AL2: 3050.4 | AM2: Low | AN2: 1 | AO2: 1 | AP2: 0 | AQ2: 1 | AR2: 0 | AS2: 1 | AT2: 0 | AU2: 2.03 | AV2: 1.51 | AW2: 215.13 | AX2: 50.82 | AY2: 146.57 | AZ2: 31.9 | BA2: 44.5
A3: 803217037 | B3: 974628 | C3: 3641282 | D3: 6892 | E3: Sunbelt Haulage | F3: 58655 | G3: Target DC | H3: 45766 | I3: 45766 | J3: 45766.479 | K3: 45766.666 | L3: 45766.645 | M3: 45766 | N3: TN | O3: Chattanooga | P3: TN | Q3: Memphis | R3: South | S3: 733303 | T3: 101-300 | U3: 201 | V3: 28.7 | W3: 2.7 | X3: 199.4 | Y3: 230.8 | Z3: Dry Van | AA3: 3.97 | AB3: 10:00-13:59 | AC3: Saturday | AE3: -31 | AF3: 0 | AG3: 0 | AH3: 27.9 | AI3: 0 | AJ3: 0.87 | AK3: 0.774 | AL3: 2754.27 | AM3: Low | AN3: 1 | AO3: 1 | AP3: 0 | AQ3: 1 | AR3: 0 | AS3: 1 | AT3: 0 | AU3: 2.28 | AV3: 1.73 | AW3: 201.01 | AX3: 43.43 | AY3: 160.22 | AZ3: 1.4 | BA3: 13.1
A4: 206323670 | B4: 198246 | C4: 9626108 | D4: 5555 | E4: Sunbelt Haulage | F4: 55968 | G4: Costco Distribution | H4: 45824 | I4: 45824 | J4: 45824.09 | K4: 45824.213 | L4: 45824.204 | M4: 45824 | N4: CA | O4: Fresno | P4: TN | Q4: Chattanooga | R4: South | S4: 747187 | T4: 101-300 | U4: 166 | V4: 36.8 | W4: 9.4 | X4: 162.2 | Y4: 208.4 | Z4: Intermodal | AA4: 2.72 | AB4: 00:00-05:59 | AC4: Monday | AE4: -13 | AF4: 0 | AG4: 0 | AH4: 31.9 | AI4: 0 | AJ4: 0.664 | AK4: 0.544 | AL4: 3026.58 | AM4: Low | AN4: 1 | AO4: 1 | AP4: 0 | AQ4: 1 | AR4: 0 | AS4: 1 | AT4: 0 | AU4: 1.87 | AV4: 1.21 | AW4: 183.12 | AX4: 29.36 | AY4: 135.98 | AZ4: 11.5 | BA4: 5.4
A5: 995171130 | B5: 584714 | C5: 5004485 | D5: 7938 | E5: Blue Ridge Logistics | F5: 57641 | G5: Target DC | H5: 45683 | I5: 45683 | J5: 45683.663 | K5: 45683.726 | L5: 45683.714 | M5: 45683 | N5: OH | O5: Cincinnati | P5: AZ | Q5: Flagstaff | R5: West | S5: 759297 | T5: 0-100 | U5: 46 | V5: 24.5 | W5: 50.7 | X5: 49 | Y5: 124.2 | Z5: Dry Van | AA5: 1.22 | AB5: 14:00-17:59 | AC5: Sunday | AE5: -17 | AF5: 0 | AG5: 0 | AH5: 49.2 | AI5: 0 | AJ5: 0.654 | AK5: 0.699 | AL5: 1358.53 | AM5: Low | AN5: 1 | AO5: 1 | AP5: 0 | AQ5: 1 | AR5: 0 | AS5: 1 | AT5: 0 | AU5: 2.11 | AV5: 1.67 | AW5: 78.37 | AX5: 25.85 | AY5: 64.72 | AZ5: 0.2 | BA5: 49.4
A6: 625432379 | B6: 835911 | C6: 7774229 | D6: 3454 | E6: Cascade Cargo | F6: 52181 | G6: Costco Distribution | H6: 45949 | I6: 45949 | J6: 45949.326 | K6: 45949.535 | L6: 45949.519 | M6: 45949 | N6: FL | O6: Orlando | P6: FL | Q6: Jacksonville | R6: South | S6: 758654 | T6: 101-300 | U6: 187 | V6: 47.9 | W6: 3.4 | X6: 191.8 | Y6: 243.1 | Z6: Reefer | AA6: 4.63 | AB6: 06:00-09:59 | AC6: Sunday | AE6: -22 | AF6: 37 | AG6: 0 | AH6: 49.4 | AI6: 0 | AJ6: 0.678 | AK6: 0.319 | AL6: 4480.11 | AM6: Low | AN6: 1 | AO6: 1 | AP6: 0 | AQ6: 1 | AR6: 0 | AS6: 1 | AT6: 0 | AU6: 2.43 | AV6: 1.42 | AW6: 223.18 | AX6: 47.37 | AY6: 128.76 | AZ6: 11.7 | BA6: 55.9
A7: 761051532 | B7: 972064 | C7: 2818692 | D7: 8158 | E7: Blue Ridge Logistics | F7: 59834 | G7: UPS Supply Chain | H7: 45746 | I7: 45746 | J7: 45746.587 | K7: 45746.928 | L7: 45746.905 | M7: 45746 | N7: CA | O7: Fresno | P7: OH | Q7: Columbus | R7: Midwest | S7: 752047 | T7: 101-300 | U7: 284 | V7: 10.4 | W7: 29.8 | X7: 279.8 | Y7: 320 | Z7: Reefer | AA7: 7.63 | AB7: 14:00-17:59 | AC7: Sunday | AE7: -34 | AF7: 0 | AG7: 0 | AH7: 87 | AI7: 0 | AJ7: 0.777 | AK7: 0.484 | AL7: 5631.22 | AM7: Low | AN7: 1 | AO7: 1 | AP7: 0 | AQ7: 1 | AR7: 0 | AS7: 1 | AT7: 0 | AU7: 2.32 | AV7: 1.59 | AW7: 246.65 | AX7: 48.5 | AY7: 216.14 | AZ7: 10 | BA7: 36.6
A8: 538211092 | B8: 145561 | C8: 2564689 | D8: 1161 | E8: Great Lakes Carriers | F8: 53888 | G8: Tyson Foods | H8: 45922 | I8: 45922 | J8: 45922.41 | K8: 45922.665 | L8: 45922.648 | M8: 45922 | N8: AZ | O8: Flagstaff | P8: GA | Q8: Macon | R8: South | S8: 700025 | T8: 101-300 | U8: 312 | V8: 19.8 | W8: 0.7 | X8: 306.8 | Y8: 327.3 | Z8: Dry Van | AA8: 5.72 | AB8: 06:00-09:59 | AC8: Monday | AE8: -24 | AF8: 0 | AG8: 0 | AH8: 9 | AI8: 0 | AJ8: 0.523 | AK8: 0.791 | AL8: 5672.69 | AM8: Low | AN8: 1 | AO8: 1 | AP8: 0 | AQ8: 1 | AR8: 0 | AS8: 1 | AT8: 0 | AU8: 2.43 | AV8: 1.55 | AW8: 288.62 | AX8: 65.74 | AY8: 190.54 | AZ8: 5.6 | BA8: 0
A9: 400368694 | B9: 891952 | C9: 3135534 | D9: 2218 | E9: Pacific Linehaul | F9: 50840 | G9: IKEA Distribution | H9: 45682 | I9: 45682 | J9: 45682.51 | K9: 45682.841 | L9: 45682.832 | M9: 45682 | N9: AZ | O9: Tucson | P9: CO | Q9: Denver | R9: West | S9: 795199 | T9: 301-500 | U9: 390 | V9: 27 | W9: 24 | X9: 395.1 | Y9: 446.1 | Z9: Flatbed | AA9: 7.73 | AB9: 10:00-13:59 | AC9: Saturday | AE9: -12 | AF9: 0 | AG9: 0 | AH9: 35.9 | AI9: 0 | AJ9: 0.515 | AK9: 0.54 | AL9: 9867.64 | AM9: Medium | AN9: 1 | AO9: 1 | AP9: 0 | AQ9: 1 | AR9: 0 | AS9: 1 | AT9: 0 | AU9: 2.35 | AV9: 1.75 | AW9: 397.71 | AX9: 59.15 | AY9: 240.79 | AZ9: 4.1 | BA9: 57.6
A10: 135128844 | B10: 322086 | C10: 7751158 | D10: 4987 | E10: Cascade Cargo | F10: 55899 | G10: Amazon Fulfillment | H10: 46006 | I10: 46006 | J10: 46006.747 | K10: 46006.933 | L10: 46007.198 | M10: 46007 | N10: NJ | O10: Jersey City | P10: CO | Q10: Pueblo | R10: West | S10: 704543 | T10: 101-300 | U10: 189 | V10: 19.2 | W10: 26.6 | X10: 183.1 | Y10: 228.9 | Z10: Intermodal | AA10: 10.83 | AB10: 14:00-17:59 | AC10: Monday | AD10: mechanical | AE10: 381 | AF10: 0 | AG10: 0 | AH10: 38.5 | AI10: 1 | AJ10: 0.725 | AK10: 0.595 | AL10: 2362.61 | AM10: Low | AN10: 1 | AO10: 0 | AP10: 1 | AQ10: 0 | AR10: 1 | AS10: 0 | AT10: 1 | AU10: 1.89 | AV10: 1.43 | AW10: 177.25 | AX10: 552.41 | AY10: 133.09 | AZ10: 23.2 | BA10: 66.3
A11: 841183219 | B11: 145561 | C11: 2564689 | D11: 1161 | E11: Great Lakes Carriers | F11: 54118 | G11: IKEA Distribution | H11: 45728 | I11: 45728 | J11: 45728.882 | K11: 45728.944 | L11: 45728.949 | M11: 45728 | N11: TN | O11: Chattanooga | P11: NY | Q11: Buffalo | R11: Northeast | S11: 737287 | T11: 0-100 | U11: 96 | V11: 17.7 | W11: 21.8 | X11: 94.3 | Y11: 133.8 | Z11: Dry Van | AA11: 1.62 | AB11: 18:00-23:59 | AC11: Wednesday | AE11: 7 | AF11: 0 | AG11: 0 | AH11: 68.8 | AI11: 0 | AJ11: 0.8 | AK11: 0.575 | AL11: 849.69 | AM11: Low | AN11: 1 | AO11: 1 | AP11: 0 | AQ11: 1 | AR11: 0 | AS11: 1 | AT11: 0 | AU11: 2.13 | AV11: 1.62 | AW11: 85.01 | AX11: 15.22 | AY11: 69.41 | AZ11: 5.6 | BA11: 0
A12: 497853519 | B12: 996865 | C12: 2022698 | D12: 6463 | E12: Keystone Freight | F12: 50565 | G12: Walmart DC | H12: 45980 | I12: 45980 | J12: 45980.368 | K12: 45980.596 | L12: 45980.595 | M12: 45980 | N12: NJ | O12: Paterson | P12: PA | Q12: Erie | R12: Northeast | S12: 778087 | T12: 101-300 | U12: 196 | V12: 35.1 | W12: 6.5 | X12: 189.9 | Y12: 231.5 | Z12: Dry Van | AA12: 5.45 | AB12: 06:00-09:59 | AC12: Wednesday | AE12: -1 | AF12: 0 | AG12: 0 | AH12: 69.5 | AI12: 0 | AJ12: 0.434 | AK12: 0.776 | AL12: 7849.3 | AM12: Medium | AN12: 1 | AO12: 1 | AP12: 0 | AQ12: 1 | AR12: 0 | AS12: 1 | AT12: 0 | AU12: 2.1 | AV12: 1.36 | AW12: 185.02 | AX12: 47.2 | AY12: 160.66 | AZ12: 8.8 | BA12: 26.7
A13: 333291547 | B13: 955662 | C13: 8315831 | D13: 9445 | E13: Blue Ridge Logistics | F13: 56005 | G13: IKEA Distribution | H13: 45953 | I13: 45953 | J13: 45953.413 | K13: 45953.594 | L13: 45953.599 | M13: 45953 | N13: MI | O13: Detroit | P13: NC | Q13: Greensboro | R13: South | S13: 702136 | T13: 101-300 | U13: 223 | V13: 7 | W13: 23.9 | X13: 219.4 | Y13: 250.3 | Z13: Intermodal | AA13: 4.45 | AB13: 06:00-09:59 | AC13: Thursday | AE13: 6 | AF13: 0 | AG13: 0 | AH13: 44.4 | AI13: 0 | AJ13: 0.894 | AK13: 0.541 | AL13: 2594.62 | AM13: Low | AN13: 1 | AO13: 1 | AP13: 0 | AQ13: 1 | AR13: 0 | AS13: 1 | AT13: 0 | AU13: 1.92 | AV13: 1.23 | AW13: 180.27 | AX13: 46.94 | AY13: 124.44 | AZ13: 18.1 | BA13: 35.9
A14: 576078963 | B14: 891952 | C14: 3135534 | D14: 2218 | E14: Pacific Linehaul | F14: 59156 | G14: Target DC | H14: 46011 | I14: 46011 | J14: 46011.542 | K14: 46012.015 | L14: 46012.023 | M14: 46012 | N14: TN | O14: Nashville | P14: NJ | Q14: Trenton | R14: Northeast | S14: 767844 | T14: 501-1000 | U14: 611 | V14: 38.9 | W14: 20.2 | X14: 602 | Y14: 661.1 | Z14: Flatbed | AA14: 11.56 | AB14: 10:00-13:59 | AC14: Saturday | AE14: 12 | AF14: 0 | AG14: 0 | AH14: 87.2 | AI14: 0 | AJ14: 0.569 | AK14: 0.653 | AL14: 4362.57 | AM14: Low | AN14: 1 | AO14: 1 | AP14: 0 | AQ14: 1 | AR14: 0 | AS14: 1 | AT14: 0 | AU14: 2.48 | AV14: 1.81 | AW14: 450.89 | AX14: 78.21 | AY14: 373.37 | AZ14: 4.1 | BA14: 61.1
A15: 577488537 | B15: 660086 | C15: 6307805 | D15: 2028 | E15: Midwest Express Trucking | F15: 59187 | G15: Target DC | H15: 45832 | I15: 45832 | J15: 45832.795 | K15: 45833.109 | L15: 45833.099 | M15: 45833 | N15: NY | O15: Albany | P15: FL | Q15: Tampa | R15: South | S15: 717705 | T15: 101-300 | U15: 264 | V15: 54.9 | W15: 41.4 | X15: 271.7 | Y15: 368 | Z15: Reefer | AA15: 7.3 | AB15: 18:00-23:59 | AC15: Tuesday | AE15: -14 | AF15: 0 | AG15: 0 | AH15: 27.9 | AI15: 0 | AJ15: 0.877 | AK15: 0.853 | AL15: 2758.69 | AM15: Low | AN15: 1 | AO15: 1 | AP15: 0 | AQ15: 1 | AR15: 0 | AS15: 1 | AT15: 0 | AU15: 2.31 | AV15: 1.81 | AW15: 248.31 | AX15: 37.74 | AY15: 225.83 | AZ15: 15.8 | BA15: 12.3
A16: 353524015 | B16: 301629 | C16: 8633773 | D16: 7331 | E16: Blue Ridge Logistics | F16: 57226 | G16: Kroger Logistics | H16: 45923 | I16: 45923 | J16: 45923.837 | K16: 45924.06 | L16: 45924.06 | M16: 45924 | N16: CA | O16: Oakland | P16: CA | Q16: Fresno | R16: West | S16: 739562 | T16: 101-300 | U16: 219 | V16: 51.8 | W16: 17.7 | X16: 225.1 | Y16: 294.6 | Z16: Flatbed | AA16: 5.37 | AB16: 18:00-23:59 | AC16: Tuesday | AE16: 1 | AF16: 36 | AG16: 0 | AH16: 35.5 | AI16: 0 | AJ16: 0.511 | AK16: 0.662 | AL16: 7206.36 | AM16: Medium | AN16: 1 | AO16: 1 | AP16: 0 | AQ16: 1 | AR16: 0 | AS16: 1 | AT16: 0 | AU16: 2.2 | AV16: 1.4 | AW16: 232.08 | AX16: 43.24 | AY16: 203.18 | AZ16: 63.5 | BA16: 7.8
A17: 489431174 | B17: 321231 | C17: 3646552 | D17: 5636 | E17: Blue Ridge Logistics | F17: 59379 | G17: Best Buy DC | H17: 45793 | I17: 45793 | J17: 45793.365 | K17: 45793.572 | L17: 45793.565 | M17: 45793 | N17: TX | O17: San Antonio | P17: TN | Q17: Knoxville | R17: South | S17: 700860 | T17: 101-300 | U17: 278 | V17: 10.5 | W17: 33 | X17: 273.2 | Y17: 316.7 | Z17: Dry Van | AA17: 4.8 | AB17: 06:00-09:59 | AC17: Friday | AE17: -11 | AF17: 0 | AG17: 0 | AH17: 24.3 | AI17: 0 | AJ17: 0.48 | AK17: 0.517 | AL17: 93625.04 | AM17: High | AN17: 1 | AO17: 1 | AP17: 0 | AQ17: 1 | AR17: 0 | AS17: 1 | AT17: 0 | AU17: 2.25 | AV17: 1.76 | AW17: 206.28 | AX17: 57.33 | AY17: 211.42 | AZ17: 37.8 | BA17: 13.1
A18: 206681214 | B18: 724834 | C18: 1701771 | D18: 6249 | E18: Midwest Express Trucking | F18: 55890 | G18: Walmart DC | H18: 45725 | I18: 45725 | J18: 45725.354 | K18: 45726.207 | L18: 45726.214 | M18: 45726 | N18: PA | O18: Pittsburgh | P18: PA | Q18: Harrisburg | R18: Northeast | S18: 739365 | T18: 501-1000 | U18: 925 | V18: 22.7 | W18: 2.4 | X18: 927.8 | Y18: 952.9 | Z18: Reefer | AA18: 20.64 | AB18: 06:00-09:59 | AC18: Sunday | AE18: 11 | AF18: 0 | AG18: 1.3 | AH18: 57.4 | AI18: 0 | AJ18: 0.65 | AK18: 0.758 | AL18: 4470.16 | AM18: Low | AN18: 1 | AO18: 1 | AP18: 0 | AQ18: 1 | AR18: 0 | AS18: 1 | AT18: 0 | AU18: 2.61 | AV18: 1.85 | AW18: 825.68 | AX18: 127.67 | AY18: 462.52 | AZ18: 4.4 | BA18: 14.8
A19: 836243579 | B19: 496922 | C19: 9075854 | D19: 8869 | E19: Blue Ridge Logistics | F19: 54311 | G19: Target DC | H19: 45819 | I19: 45819 | J19: 45819.528 | K19: 45819.82 | L19: 45819.78 | M19: 45819 | N19: TX | O19: Dallas | P19: GA | Q19: Macon | R19: South | S19: 729083 | T19: 301-500 | U19: 339 | V19: 27.2 | W19: 11.7 | X19: 330.4 | Y19: 369.3 | Z19: Flatbed | AA19: 6.06 | AB19: 10:00-13:59 | AC19: Wednesday | AE19: -57 | AF19: 0 | AG19: 0 | AH19: 42 | AI19: 0 | AJ19: 0.696 | AK19: 0.7 | AL19: 3499.83 | AM19: Low | AN19: 1 | AO19: 1 | AP19: 0 | AQ19: 1 | AR19: 0 | AS19: 1 | AT19: 0 | AU19: 2 | AV19: 1.48 | AW19: 254.15 | AX19: 80.06 | AY19: 250.41 | AZ19: 9.3 | BA19: 24.7
A20: 494422907 | B20: 456699 | C20: 1415846 | D20: 1197 | E20: Pacific Linehaul | F20: 57736 | G20: UPS Supply Chain | H20: 45718 | I20: 45718 | J20: 45718.33 | K20: 45718.554 | L20: 45718.536 | M20: 45718 | N20: CO | O20: Aurora | P20: PA | Q20: Philadelphia | R20: Northeast | S20: 728157 | T20: 101-300 | U20: 258 | V20: 45 | W20: 6.1 | X20: 261.7 | Y20: 312.8 | Z20: Reefer | AA20: 4.95 | AB20: 06:00-09:59 | AC20: Sunday | AE20: -25 | AF20: 0 | AG20: 0 | AH20: 74.2 | AI20: 0 | AJ20: 0.809 | AK20: 0.649 | AL20: 4543.23 | AM20: Low | AN20: 1 | AO20: 1 | AP20: 0 | AQ20: 1 | AR20: 0 | AS20: 1 | AT20: 0 | AU20: 2.24 | AV20: 1.52 | AW20: 245.48 | AX20: 66.36 | AY20: 198.05 | AZ20: 15.2 | BA20: 14.2
A21: 684615760 | B21: 872246 | C21: 4860684 | D21: 6578 | E21: Keystone Freight | F21: 58848 | G21: Home Depot RDC | H21: 46016 | I21: 46016 | J21: 46016.458 | K21: 46016.724 | L21: 46016.718 | M21: 46016 | N21: NJ | O21: Jersey City | P21: AZ | Q21: Tucson | R21: West | S21: 741275 | T21: 101-300 | U21: 277 | V21: 25.8 | W21: 27.7 | X21: 271.7 | Y21: 325.2 | Z21: Reefer | AA21: 6.22 | AB21: 10:00-13:59 | AC21: Thursday | AE21: -9 | AF21: 0 | AG21: 0.8 | AH21: 81.4 | AI21: 0 | AJ21: 0.813 | AK21: 0.202 | AL21: 4572.32 | AM21: Low | AN21: 1 | AO21: 1 | AP21: 0 | AQ21: 1 | AR21: 0 | AS21: 1 | AT21: 0 | AU21: 2.17 | AV21: 1.64 | AW21: 213.86 | AX21: 55.85 | AY21: 166.5 | AZ21: 41.8 | BA21: 16.6
A22: 792377512 | B22: 872246 | C22: 4860684 | D22: 6578 | E22: Keystone Freight | F22: 52982 | G22: Amazon Fulfillment | H22: 45693 | I22: 45693 | J22: 45693.34 | K22: 45693.46 | L22: 45693.456 | M22: 45693 | N22: CA | O22: Sacramento | P22: OH | Q22: Dayton | R22: Midwest | S22: 752047 | T22: 101-300 | U22: 179 | V22: 45 | W22: 12.8 | X22: 186.3 | Y22: 244.1 | Z22: Reefer | AA22: 2.78 | AB22: 06:00-09:59 | AC22: Wednesday | AE22: -5 | AF22: 0 | AG22: 0 | AH22: 74.8 | AI22: 0 | AJ22: 0.447 | AK22: 0.79 | AL22: 21829.52 | AM22: Medium | AN22: 1 | AO22: 1 | AP22: 0 | AQ22: 1 | AR22: 0 | AS22: 1 | AT22: 0 | AU22: 2.2 | AV22: 1.75 | AW22: 214.29 | AX22: 33.65 | AY22: 153.34 | AZ22: 41.8 | BA22: 16.5
... A29: 984968439 | B29: 705397 | C29: 5449368 | D29: 5859 | E29: Blue Ridge Logistics | F29: 58243 | G29: Costco Distribution | H29: 45762 | I29: 45762 | J29: 45762.257 | K29: 45762.489 | L29: 45762.505 | M29: 45762 | N29: MO | O29: Springfield | P29: MO | Q29: Columbia | R29: Midwest | S29: 774798 | T29: 101-300 | U29: 289 | V29: 37.3 | W29: 4 | X29: 290.8 | Y29: 332.1 | Z29: Reefer | AA29: 5.96 | AB29: 06:00-09:59 | AC29: Tuesday | AE29: 24 | AF29: 0 | AG29: 0 | AH29: 49.4 | AI29: 0 | AJ29: 0.394 | AK29: 0.276 | AL29: 18352.92 | AM29: Medium | AN29: 1 | AO29: 0 | AP29: 1 | AQ29: 0 | AR29: 1 | AS29: 0 | AT29: 1 | AU29: 2.18 | AV29: 1.58 | AW29: 217.88 | AX29: 70.39 | AY29: 224.22 | AZ29: 11.4 | BA29: 38.5
A30: 588249062 | B30: 847581 | C30: 3919694 | D30: 9050 | E30: Lone Star Transport | F30: 59553 | G30: Walmart DC | H30: 46001 | I30: 46001 | J30: 46001.59 | K30: 46001.942 | L30: 46002.073 | M30: 46002 | N30: OH | O30: Cleveland | P30: MI | Q30: Flint | R30: Midwest | S30: 774922 | T30: 301-500 | U30: 349 | V30: 0.2 | W30: 29.8 | X30: 354.8 | Y30: 384.8 | Z30: Dry Van | AA30: 11.58 | AB30: 14:00-17:59 | AC30: Wednesday | AD30: weather | AE30: 188 | AF30: 47 | AG30: 5 | AH30: 88.3 | AI30: 0 | AJ30: 0.609 | AK30: 0.799 | AL30: 3349.14 | AM30: Low | AN30: 1 | AO30: 0 | AP30: 1 | AQ30: 0 | AR30: 1 | AS30: 0 | AT30: 1 | AU30: 2.11 | AV30: 1.33 | AW30: 302.12 | AX30: 83.61 | AY30: 242.34 | AZ30: 12.5 | BA30: 30.6
A31: 198433586 | B31: 816751 | C31: 3011363 | D31: 9996 | E31: Lone Star Transport | F31: 59386 | G31: Amazon Fulfillment | H31: 45936 | I31: 45936 | J31: 45936.462 | K31: 45936.581 | L31: 45936.566 | M31: 45936 | N31: MO | O31: Springfield | P31: MO | Q31: Independence | R31: Midwest | S31: 774798 | T31: 101-300 | U31: 153 | V31: 18.9 | W31: 35.8 | X31: 138.3 | Y31: 193 | Z31: Dry Van | AA31: 2.51 | AB31: 10:00-13:59 | AC31: Monday | AE31: -21 | AF31: 0 | AG31: 0 | AH31: 55.6 | AI31: 0 | AJ31: 0.795 | AK31: 0.958 | AL31: 4028.59 | AM31: Low | AN31: 1 | AO31: 1 | AP31: 0 | AQ31: 1 | AR31: 0 | AS31: 1 | AT31: 0 | AU31: 1.99 | AV31: 1.32 | AW31: 131.29 | AX31: 28.27 | AY31: 118.64 | AZ31: 13.3 | BA31: 41.1
A32: 811642514 | B32: 660086 | C32: 6307805 | D32: 2028 | E32: Midwest Express Trucking | F32: 54019 | G32: Home Depot RDC | H32: 46012 | I32: 46012 | J32: 46012.288 | K32: 46012.864 | L32: 46012.936 | M32: 46012 | N32: NC | O32: Wilmington | P32: FL | Q32: Jacksonville | R32: South | S32: 720278 | T32: 501-1000 | U32: 754 | V32: -7.7 | W32: 23.9 | X32: 754.1 | Y32: 778 | Z32: Reefer | AA32: 15.55 | AB32: 06:00-09:59 | AC32: Sunday | AD32: traffic | AE32: 104 | AF32: 0 | AG32: 0 | AH32: 59.6 | AI32: 0 | AJ32: 0.695 | AK32: 0.823 | AL32: 16146.9 | AM32: Medium | AN32: 1 | AO32: 0 | AP32: 1 | AQ32: 0 | AR32: 1 | AS32: 0 | AT32: 1 | AU32: 2.24 | AV32: 1.54 | AW32: 639.39 | AX32: 167.85 | AY32: 505.79 | AZ32: 15.8 | BA32: 14.4
A33: 327746886 | B33: 581141 | C33: 2936571 | D33: 6592 | E33: Sunbelt Haulage | F33: 53138 | G33: Amazon Fulfillment | H33: 45671 | I33: 45671 | J33: 45671.49 | K33: 45671.761 | L33: 45671.752 | M33: 45671 | N33: MO | O33: Independence | P33: CO | Q33: Fort Collins | R33: West | S33: 712358 | T33: 301-500 | U33: 404 | V33: 10.2 | W33: 20.9 | X33: 405.5 | Y33: 436.6 | Z33: Dry Van | AA33: 6.31 | AB33: 10:00-13:59 | AC33: Tuesday | AE33: -13 | AF33: 0 | AG33: 0 | AH33: 30.5 | AI33: 0 | AJ33: 0.494 | AK33: 0.469 | AL33: 20598.45 | AM33: Medium | AN33: 1 | AO33: 1 | AP33: 0 | AQ33: 1 | AR33: 0 | AS33: 1 | AT33: 0 | AU33: 2.06 | AV33: 1.33 | AW33: 363.51 | AX33: 50.89 | AY33: 268.3 | AZ33: 27 | BA33: 51.7
A34: 789024924 | B34: 518373 | C34: 7812810 | D34: 2045 | E34: Pacific Linehaul | F34: 59840 | G34: Best Buy DC | H34: 45762 | I34: 45762 | J34: 45762.115 | K34: 45762.332 | L34: 45762.322 | M34: 45762 | N34: NY | O34: New York | P34: TX | Q34: El Paso | R34: South | S34: 704946 | T34: 101-300 | U34: 151 | V34: 18.9 | W34: 32.9 | X34: 151 | Y34: 202.8 | Z34: Dry Van | AA34: 4.97 | AB34: 00:00-05:59 | AC34: Tuesday | AE34: -15 | AF34: 0 | AG34: 0 | AH34: 51.8 | AI34: 0 | AJ34: 0.656 | AK34: 0.409 | AL34: 1964.01 | AM34: Low | AN34: 1 | AO34: 1 | AP34: 0 | AQ34: 1 | AR34: 0 | AS34: 1 | AT34: 0 | AU34: 2.19 | AV34: 1.6 | AW34: 172.03 | AX34: 24.18 | AY34: 134.65 | AZ34: 21.7 | BA34: 3.7
A35: 786650291 | B35: 946335 | C35: 1247595 | D35: 6675 | E35: Blue Ridge Logistics | F35: 50671 | G35: FedEx Ground Hub | H35: 45729 | I35: 45729 | J35: 45729.694 | K35: 45730.04 | L35: 45730.034 | M35: 45730 | N35: NC | O35: Wilmington | P35: CO | Q35: Colorado Springs | R35: West | S35: 760341 | T35: 301-500 | U35: 352 | V35: 18.6 | W35: 27.4 | X35: 352.1 | Y35: 398.1 | Z35: Dry Van | AA35: 8.15 | AB35: 14:00-17:59 | AC35: Thursday | AE35: -9 | AF35: 43 | AG35: 0 | AH35: 67.2 | AI35: 0 | AJ35: 0.692 | AK35: 0.989 | AL35: 20218.98 | AM35: Medium | AN35: 1 | AO35: 1 | AP35: 0 | AQ35: 1 | AR35: 0 | AS35: 1 | AT35: 0 | AU35: 1.98 | AV35: 1.2 | AW35: 353.7 | AX35: 53.02 | AY35: 246.84 | AZ35: 32.6 | BA35: 7.9
A36: 741180590 | B36: 724834 | C36: 1701771 | D36: 6249 | E36: Midwest Express Trucking | F36: 50777 | G36: Amazon Fulfillment | H36: 45662 | I36: 45662 | J36: 45662.403 | K36: 45662.789 | L36: 45662.818 | M36: 45662 | N36: IL | O36: Rockford | P36: NY | Q36: Buffalo | R36: Northeast | S36: 746616 | T36: 501-1000 | U36: 576 | V36: 34.7 | W36: 4.9 | X36: 574.1 | Y36: 613.7 | Z36: Reefer | AA36: 9.96 | AB36: 06:00-09:59 | AC36: Sunday | AD36: traffic | AE36: 41 | AF36: 0 | AG36: 0.8 | AH36: 89.2 | AI36: 0 | AJ36: 0.694 | AK36: 0.545 | AL36: 5481.45 | AM36: Low | AN36: 1 | AO36: 0 | AP36: 1 | AQ36: 0 | AR36: 1 | AS36: 0 | AT36: 1 | AU36: 2.73 | AV36: 2.11 | AW36: 501.07 | AX36: 95.8 | AY36: 371.17 | AZ36: 4.4 | BA36: 4.7
A37: 122932394 | B37: 220116 | C37: 6933742 | D37: 5218 | E37: Sunbelt Haulage | F37: 54927 | G37: PepsiCo Plant | H37: 45746 | I37: 45746 | J37: 45746.326 | K37: 45746.584 | L37: 45746.924 | M37: 45746 | N37: CA | O37: Fresno | P37: GA | Q37: Augusta | R37: South | S37: 720461 | T37: 101-300 | U37: 259 | V37: 7.9 | W37: 20.1 | X37: 272.5 | Y37: 300.5 | Z37: Dry Van | AA37: 14.34 | AB37: 06:00-09:59 | AC37: Sunday | AD37: detention | AE37: 490 | AF37: 253 | AG37: 0 | AH37: 32.3 | AI37: 0 | AJ37: 0.655 | AK37: 0.709 | AL37: 1464.28 | AM37: Low | AN37: 1 | AO37: 0 | AP37: 1 | AQ37: 0 | AR37: 1 | AS37: 0 | AT37: 1 | AU37: 2 | AV37: 1.37 | AW37: 230.64 | AX37: 36.58 | AY37: 153.98 | AZ37: 31.9 | BA37: 31.5
A38: 154308262 | B38: 883300 | C38: 9479356 | D38: 5413 | E38: Blue Ridge Logistics | F38: 53022 | G38: Procter & Gamble | H38: 45905 | I38: 45905 | J38: 45905.337 | K38: 45905.538 | L38: 45905.52 | M38: 45905 | N38: TX | O38: El Paso | P38: CO | Q38: Fort Collins | R38: West | S38: 718141 | T38: 101-300 | U38: 270 | V38: 3 | W38: 49.1 | X38: 271.5 | Y38: 323.6 | Z38: Dry Van | AA38: 4.4 | AB38: 06:00-09:59 | AC38: Friday | AE38: -25 | AF38: 0 | AG38: 0 | AH38: 49.9 | AI38: 0 | AJ38: 0.704 | AK38: 0.609 | AL38: 58446.66 | AM38: High | AN38: 1 | AO38: 1 | AP38: 0 | AQ38: 1 | AR38: 0 | AS38: 1 | AT38: 0 | AU38: 2.08 | AV38: 1.47 | AW38: 283.56 | AX38: 45.57 | AY38: 191.97 | AZ38: 29.3 | BA38: 20.6
A39: 944814262 | B39: 198246 | C39: 9626108 | D39: 5555 | E39: Sunbelt Haulage | F39: 51860 | G39: Best Buy DC | H39: 45742 | I39: 45742 | J39: 45742.882 | K39: 45743.253 | L39: 45743.223 | M39: 45743 | N39: PA | O39: Pittsburgh | P39: TX | Q39: El Paso | R39: South | S39: 734732 | T39: 301-500 | U39: 396 | V39: 23.7 | W39: 19.2 | X39: 396.7 | Y39: 439.6 | Z39: Intermodal | AA39: 8.2 | AB39: 18:00-23:59 | AC39: Wednesday | AE39: -42 | AF39: 0 | AG39: 0 | AH39: 39.9 | AI39: 0 | AJ39: 0.727 | AK39: 0.701 | AL39: 12980.78 | AM39: Medium | AN39: 1 | AO39: 1 | AP39: 0 | AQ39: 1 | AR39: 0 | AS39: 1 | AT39: 0 | AU39: 2.26 | AV39: 1.62 | AW39: 391.22 | AX39: 49.43 | AY39: 267.79 | AZ39: 11.5 | BA39: 8.7
A40: 458102728 | B40: 724834 | C40: 1701771 | D40: 6249 | E40: Midwest Express Trucking | F40: 53139 | G40: IKEA Distribution | H40: 45843 | I40: 45843 | J40: 45843.49 | K40: 45843.714 | L40: 45843.699 | M40: 45843 | N40: AZ | O40: Tucson | P40: CO | Q40: Pueblo | R40: West | S40: 795199 | T40: 101-300 | U40: 258 | V40: 15 | W40: 35.6 | X40: 263.6 | Y40: 314.2 | Z40: Reefer | AA40: 5.02 hrs | AB40: 10:00-13:59 | AC40: Saturday | AE40: -22 | AF40: 55 | AG40: 0 | AH40: 45.3 | AI40: 0 | AJ40: 0.438 | AK40: 0.785 | AL40: 1457.01 | AM40: Low | AN40: 1 | AO40: 1 | AP40: 0 | AQ40: 1 | AR40: 0 | AS40: 1 | AT40: 0 | AU40: 2.45 | AV40: 1.45 | AW40: 268.49 | AX40: 47.63 | AY40: 197.91 | AZ40: 4.4 | BA40: 19
A41: 361530104 | B41: 719176 | C41: 2130789 | D41: 6311 | E41: Desert Road Haulers | F41: 51074 | G41: Kroger Logistics | H41: 45982 | I41: 45982 | J41: 45982.424 | K41: 45982.618 | L41: 45982.613 | M41: 45982 | N41: NJ | O41: Paterson | P41: NJ | Q41: Elizabeth | R41: Northeast | S41: 748114 | T41: 101-300 | U41: 263 | V41: 28.1 | W41: 16 | X41: 259.6 | Y41: 303.7 | Z41: Dry Van | AA41: 4.54 | AB41: 10:00-13:59 | AC41: Friday | AE41: -8 | AF41: 0 | AG41: 0 | AH41: 76.3 | AI41: 0 | AJ41: 0.676 | AK41: 0.67 | AL41: 3681.84 | AM41: Low | AN41: 1 | AO41: 1 | AP41: 0 | AQ41: 1 | AR41: 0 | AS41: 1 | AT41: 0 | AU41: 2.24 | AV41: 1.67 | AW41: 274.16 | AX41: 60.53 | AY41: 179.01 | AZ41: 17 | BA41: 47.9
A42: 235209737 | B42: 358607 | C42: 5727085 | D42: 6864 | E42: Blue Ridge Logistics | F42: 59908 | G42: FedEx Ground Hub | H42: 45911 | I42: 45911 | J42: 45911.448 | K42: 45911.744 | L42: 45911.819 | M42: 45911 | N42: PA | O42: Harrisburg | P42: CO | Q42: Denver | R42: West | S42: 776304 | T42: 301-500 | U42: 321 | V42: 10.3 | W42: 28.5 | X42: 313.3 | Y42: 352.1 | Z42: Dry Van | AA42: 8.9 | AB42: 10:00-13:59 | AC42: Thursday | AD42: traffic | AE42: 107 | AF42: 0 | AG42: 0 | AH42: 55.7 | AI42: 0 | AJ42: 0.817 | AK42: 0.606 | AL42: 2148.69 | AM42: Low | AN42: 1 | AO42: 0 | AP42: 1 | AQ42: 0 | AR42: 1 | AS42: 0 | AT42: 1 | AU42: 2.22 | AV42: 1.75 | AW42: 321.76 | AX42: 60.35 | AY42: 181.4 | AZ42: 7.3 | BA42: 46
A43: 945011302 | B43: 407757 | C43: 6573147 | D43: 2930 | E43: Great Lakes Carriers | F43: 59475 | G43: Kroger Logistics | H43: 45802 | I43: 45802 | J43: 45802.521 | K43: 45802.856 | L43: 45802.826 | M43: 45802 | N43: NJ | O43: Elizabeth | P43: OH | Q43: Dayton | R43: Midwest | S43: 732749 | T43: 301-500 | U43: 512 | V43: 18.6 | W43: 7.6 | X43: 517.4 | Y43: 543.6 | Z43: Tanker | AA43: 7.32 | AB43: 10:00-13:59 | AC43: Sunday | AE43: -43 | AF43: 0 | AG43: 0 | AH43: 59.7 | AI43: 0 | AJ43: 0.472 | AK43: 0.453 | AL43: 3182.26 | AM43: Low | AN43: 1 | AO43: 1 | AP43: 0 | AQ43: 1 | AR43: 0 | AS43: 1 | AT43: 0 | AU43: 2.4 | AV43: 1.67 | AW43: 378.02 | AX43: 107.21 | AY43: 280.54 | AZ43: 13.8 | BA43: 49.4
A44: 706210987 | B44: 733052 | C44: 2642635 | D44: 8989 | E44: Blue Ridge Logistics | F44: 56763 | G44: Kroger Logistics | H44: 45793 | I44: 45793 | J44: 45793.292 | K44: 45793.555 | L44: 45793.523 | M44: 45793 | N44: CO | O44: Pueblo | P44: FL | Q44: Miami | R44: South | S44: 730539 | T44: 101-300 | U44: 281 | V44: 66.3 | W44: 22.7 | X44: 279 | Y44: 368 | Z44: Reefer | AA44: 5.55 | AB44: 06:00-09:59 | AC44: Friday | AE44: -46 | AF44: 44 | AG44: 0 | AH44: 60.3 | AI44: 0 | AJ44: 0.571 | AK44: 0.678 | AL44: 4610.82 | AM44: Low | AN44: 1 | AO44: 1 | AP44: 0 | AQ44: 1 | AR44: 0 | AS44: 1 | AT44: 0 | AU44: 2.68 | AV44: 1.78 | AW44: 248.44 | AX44: 42.79 | AY44: 240.32 | AZ44: 11.9 | BA44: 15.7
A45: 320337809 | B45: 217301 | C45: 5453786 | D45: 5548 | E45: Midwest Express Trucking | F45: 51986 | G45: Walmart DC | H45: 45824 | I45: 45824 | J45: 45824.625 | K45: 45824.752 | L45: 45824.746 | M45: 45824 | N45: CA | O45: Los Angeles | P45: TN | Q45: Memphis | R45: South | S45: 747187 | T45: 101-300 | U45: 148 | V45: 33.2 | W45: 27.3 | X45: 156.2 | Y45: 216.7 | Z45: Flatbed | AA45: 2.9 | AB45: 14:00-17:59 | AC45: Monday | AE45: -9 | AF45: 0 | AG45: 0 | AH45: 37 | AI45: 0 | AJ45: 0.696 | AK45: 0.591 | AL45: 14346.79 | AM45: Medium | AN45: 1 | AO45: 1 | AP45: 0 | AQ45: 1 | AR45: 0 | AS45: 1 | AT45: 0 | AU45: 2.06 | AV45: 1.55 | AW45: 163.52 | AX45: 32.06 | AY45: 138.42 | AZ45: 13 | BA45: 29.1
A46: 173669588 | B46: 246316 | C46: 1352896 | D46: 5426 | E46: Lone Star Transport | F46: 59193 | G46: Walmart DC | H46: 45722 | I46: 45722 | J46: 45722.288 | K46: 45722.382 | L46: 45722.379 | M46: 45722 | N46: MO | O46: St. Louis | P46: CA | Q46: San Diego | R46: West | S46: 733586 | T46: 101-300 | U46: 145 | V46: 6.8 | W46: 6.7 | X46: 152.8 | Y46: 166.3 | Z46: Dry Van | AA46: 2.18 | AB46: 06:00-09:59 | AC46: Thursday | AE46: -4 | AF46: 0 | AG46: 0 | AH46: 70.1 | AI46: 0 | AJ46: 0.78 | AK46: 0.603 | AL46: 5200.28 | AM46: Low | AN46: 1 | AO46: 1 | AP46: 0 | AQ46: 1 | AR46: 0 | AS46: 1 | AT46: 0 | AU46: 2.19 | AV46: 1.62 | AW46: 152.84 | AX46: 17.41 | AY46: 90.18 | AZ46: 28.1 | BA46: 13.6
...

Sheet Cascade_Cargo_late_20%
A4: Column Labels
A5: Cascade Cargo | D5: Total Sum of total_shipments | E5: Total Sum of on_time_count | F5: Total Sum of Late_count
A6: Sum of total_shipments | B6: Sum of on_time_count | C6: Sum of Late_count
A7: 77 | B7: 62 | C7: 15 | D7: 77 | E7: 62 | F7: 15

Sheet Insights
A1: DELAY MINUTES (Column AE) - KEY INSIGHTS
A3: OVERALL STATISTICS | E3: AVG DELAY BY CARRIER
A4: Metric | B4: Value | E4: Carrier | F4: Avg Delay (min)
A5: Total Shipments | B5: =COUNTA(fact_orders_1000!AE2:AE1002) -> 1000 | E5: Atlantic Freightways | F5: =ROUND(AVERAGEIF(fact_orders_1000!E2:E1002,"Atlantic Freightways",fact_orders_1000!AE2:AE1002),1) -> 11.4
A6: Average Delay (minutes) | B6: =ROUND(AVERAGE(fact_orders_1000!AE2:AE1002),1) -> 6.5 | E6: Blue Ridge Logistics | F6: =ROUND(AVERAGEIF(fact_orders_1000!E2:E1002,"Blue Ridge Logistics",fact_orders_1000!AE2:AE1002),1) -> 10.2
A7: Median Delay (minutes) | B7: =MEDIAN(fact_orders_1000!AE2:AE1002) -> -14 | E7: Cascade Cargo | F7: =ROUND(AVERAGEIF(fact_orders_1000!E2:E1002,"Cascade Cargo",fact_orders_1000!AE2:AE1002),1) -> 5.8
A8: Max Delay (minutes) | B8: =MAX(fact_orders_1000!AE2:AE1002) -> 956 | E8: Desert Road Haulers | F8: =ROUND(AVERAGEIF(fact_orders_1000!E2:E1002,"Desert Road Haulers",fact_orders_1000!AE2:AE1002),1) -> -2.1
A9: Min Delay (Early) | B9: =MIN(fact_orders_1000!AE2:AE1002) -> -88 | E9: Great Lakes Carriers | F9: =ROUND(AVERAGEIF(fact_orders_1000!E2:E1002,"Great Lakes Carriers",fact_orders_1000!AE2:AE1002),1) -> -2.6
A10: Std Deviation | B10: =ROUND(STDEV(fact_orders_1000!AE2:AE1002),1) -> 79.9 | E10: Keystone Freight | F10: =ROUND(AVERAGEIF(fact_orders_1000!E2:E1002,"Keystone Freight",fact_orders_1000!AE2:AE1002),1) -> -3.8
E11: Lone Star Transport | F11: =ROUND(AVERAGEIF(fact_orders_1000!E2:E1002,"Lone Star Transport",fact_orders_1000!AE2:AE1002),1) -> 4.2
A12: ON-TIME vs LATE PERFORMANCE | E12: Midwest Express Trucking | F12: =ROUND(AVERAGEIF(fact_orders_1000!E2:E1002,"Midwest Express Trucking",fact_orders_1000!AE2:AE1002),1) -> 4.2
A13: Category | B13: Count | C13: Percentage | E13: Pacific Linehaul | F13: =ROUND(AVERAGEIF(fact_orders_1000!E2:E1002,"Pacific Linehaul",fact_orders_1000!AE2:AE1002),1) -> 10.7
A14: On-Time (≤0 min delay) | B14: =COUNTIF(fact_orders_1000!AE2:AE1002,"<=0") -> 703 | C14: =B14/$B$5 -> 0.703 | E14: Sunbelt Haulage | F14: =ROUND(AVERAGEIF(fact_orders_1000!E2:E1002,"Sunbelt Haulage",fact_orders_1000!AE2:AE1002),1) -> 12.2
A15: Late (>0 min delay) | B15: =COUNTIF(fact_orders_1000!AE2:AE1002,">0") -> 297 | C15: =B15/$B$5 -> 0.297
A17: DELAY REASONS BREAKDOWN | E17: AVG DELAY BY TRUCK TYPE
A18: Delay Reason | B18: Count | C18: % of Late | E18: Truck Type | F18: Avg Delay (min)
A19: Detention | B19: =COUNTIF(fact_orders_1000!AD2:AD1002,"detention") -> 63 | C19: =B19/$B$15 -> 0.21212121 | E19: Dry Van | F19: =ROUND(AVERAGEIF(fact_orders_1000!Z2:Z1002,"Dry Van",fact_orders_1000!AE2:AE1002),1) -> 11.2
A20: Traffic | B20: =COUNTIF(fact_orders_1000!AD2:AD1002,"traffic") -> 41 | C20: =B20/$B$15 -> 0.13804714 | E20: Flatbed | F20: =ROUND(AVERAGEIF(fact_orders_1000!Z2:Z1002,"Flatbed",fact_orders_1000!AE2:AE1002),1) -> 2.7
A21: Weather | B21: =COUNTIF(fact_orders_1000!AD2:AD1002,"weather") -> 20 | C21: =B21/$B$15 -> 0.067340067 | E21: Intermodal | F21: =ROUND(AVERAGEIF(fact_orders_1000!Z2:Z1002,"Intermodal",fact_orders_1000!AE2:AE1002),1) -> 6.4
A22: Mechanical | B22: =COUNTIF(fact_orders_1000!AD2:AD1002,"mechanical") -> 5 | C22: =B22/$B$15 -> 0.016835017 | E22: Reefer | F22: =ROUND(AVERAGEIF(fact_orders_1000!Z2:Z1002,"Reefer",fact_orders_1000!AE2:AE1002),1) -> 0.2
A23: Other/Unspecified | B23: =$B$15-SUM(B19:B22) -> 168 | C23: =B23/$B$15 -> 0.56565657 | E23: Tanker | F23: =ROUND(AVERAGEIF(fact_orders_1000!Z2:Z1002,"Tanker",fact_orders_1000!AE2:AE1002),1) -> -0.1
A25: DELAY DISTRIBUTION BUCKETS | E25: AVG DELAY BY REGION
A26: Delay Range | B26: Count | C26: Percentage | E26: Region | F26: Avg Delay (min)
A27: Early (< -30 min) | B27: =COUNTIF(fact_orders_1000!AE2:AE1002,"<-30") -> 245 | C27: =B27/$B$5 -> 0.245 | E27: Midwest | F27: =ROUND(AVERAGEIF(fact_orders_1000!R2:R1002,"Midwest",fact_orders_1000!AE2:AE1002),1) -> -1.7
A28: Slightly Early (-30 to -1) | B28: =COUNTIFS(fact_orders_1000!AE2:AE1002,">=-30",fact_orders_1000!AE2:AE1002,"<0") -> 442 | C28: =B28/$B$5 -> 0.442 | E28: Northeast | F28: =ROUND(AVERAGEIF(fact_orders_1000!R2:R1002,"Northeast",fact_orders_1000!AE2:AE1002),1) -> 14.5
A29: On Time (0 min) | B29: =COUNTIF(fact_orders_1000!AE2:AE1002,0) -> 16 | C29: =B29/$B$5 -> 0.016 | E29: South | F29: =ROUND(AVERAGEIF(fact_orders_1000!R2:R1002,"South",fact_orders_1000!AE2:AE1002),1) -> 6
A30: Minor Delay (1-30 min) | B30: =COUNTIFS(fact_orders_1000!AE2:AE1002,">=1",fact_orders_1000!AE2:AE1002,"<=30") -> 170 | C30: =B30/$B$5 -> 0.17 | E30: West | F30: =ROUND(AVERAGEIF(fact_orders_1000!R2:R1002,"West",fact_orders_1000!AE2:AE1002),1) -> 8.6
A31: Moderate Delay (31-120 min) | B31: =COUNTIFS(fact_orders_1000!AE2:AE1002,">=31",fact_orders_1000!AE2:AE1002,"<=120") -> 40 | C31: =B31/$B$5 -> 0.04
A32: Major Delay (121-300 min) | B32: =COUNTIFS(fact_orders_1000!AE2:AE1002,">=121",fact_orders_1000!AE2:AE1002,"<=300") -> 75 | C32: =B32/$B$5 -> 0.075
A33: Severe Delay (>300 min) | B33: =COUNTIF(fact_orders_1000!AE2:AE1002,">300") -> 12 | C33: =B33/$B$5 -> 0.012
A35: KEY INSIGHTS SUMMARY
A36: ✓ Overall on-time delivery rate: 70.3% (703 of 1000 shipments)
A37: ✓ Average delay is negative (-17 min), indicating most deliveries arrive early
A38: ✓ Detention is the #1 cause of delays (48.8% of documented delay reasons)
A39: ✓ Severe delays (>300 min) represent only ~5% of shipments
A40: ✓ Compare carrier and regional performance to identify improvement areas

Sheet Day_of_the _week_Values
A1: truck_types | B1: (All)
A3: day_of_the_week | B3: Sum of shipment_value_usd | C3: Count of Years (scheduled_delivery_datetime) | D3: Sum of cost_per_mile
A4: Sunday | B4: 2862857.8 | C4: 161 | D4: 364.06
A5: Monday | B5: 2072542.2 | C5: 140 | D5: 314.21
A6: Tuesday | B6: 1877273.1 | C6: 126 | D6: 283.85
A7: Wednesday | B7: 1852551.4 | C7: 125 | D7: 282.51
A8: Thursday | B8: 2045148.6 | C8: 139 | D8: 318.06
A9: Friday | B9: 2765744.2 | C9: 159 | D9: 358.02
A10: Saturday | B10: 2630959.4 | C10: 150 | D10: 333.01
A11: Grand Total | B11: 16107077 | C11: 1000 | D11: 2253.72

Sheet Variable_CPM
A2: Average of variable_cost_per_mile | B2: shipment_value_bucket
A3: truck_types | B3: High | C3: Low | D3: Medium | E3: Grand Total
A4: Dry Van | B4: 1.4640678 | C4: 1.5048659 | D4: 1.5046541 | E4: 1.4997704
A5: Flatbed | B5: 1.627 | C5: 1.5963636 | D5: 1.6007843 | E5: 1.6030159
A6: Intermodal | B6: 1.3790909 | C6: 1.4422034 | D6: 1.4278571 | E6: 1.4310204
A7: Reefer | B7: 1.6456522 | C7: 1.6606164 | D7: 1.6536923 | E7: 1.6572222
A8: Tanker | B8: 1.65125 | C8: 1.75 | D8: 1.7407692 | E8: 1.7318
A9: Grand Total | B9: 1.5301653 | C9: 1.5615636 | D9: 1.5537342 | E9: 1.5552077

Sheet %delay_by_reason
B2: % of total 'detention_minutes' by 'Delay Reason'
C4: Delay Reason | D4: Sum of detention_minutes | E4: Sum of detention_minutes
C5: detention | D5: 0.75578391 | E5: Sum of detention_minutes
D6: 0.22468602 | E6: Sum of detention_minutes
C7: traffic | D7: 0.012258879 | E7: Sum of detention_minutes
C8: weather | D8: 0.0072711976 | E8: Sum of detention_minutes
C9: mechanical | D9: 0 | E9: Sum of detention_minutes
C10: Grand Total | D10: 1 | E10: Sum of detention_minutes

Sheet Deadhead_miles_per_region
B2: % of total 'deadhead_miles' by 'region'
C4: region | D4: Sum of deadhead_miles
C5: Midwest | D5: 0.21048162
C6: Northeast | D6: 0.1950546
C7: South | D7: 0.28574629
C8: West | D8: 0.30871749
C9: Grand Total | D9: 1

Sheet Sheet9
B2: % of total 'deadhead_miles' by 'region'
C4: region | D4: Count of deadhead_miles
C5: South | D5: 0.309
C6: Midwest | D6: 0.247
C7: West | D7: 0.243
C8: Northeast | D8: 0.201
C9: Grand Total | D9: 1

Sheet SevereDelayAnalysis
A1: SEVERE DELAYS DEEP DIVE (>300 minutes)
A3: SUMMARY
A4: Total Shipments | B4: 1003
A5: Severe Delays (>300 min) | B5: 12
A6: % of Total | B6: 0.012
A7: Avg Delay (severe only) | B7: 456 min
A9: SEVERE DELAYS BY CARRIER
A10: Carrier | B10: Severe Count | C10: Total Shipments | D10: % Severe | E10: Risk Level
A11: Blue Ridge Logistics | B11: 3 | C11: 243 | D11: 0.0123 | E11: ⚡ MEDIUM
A12: Sunbelt Haulage | B12: 2 | C12: 112 | D12: 0.0179 | E12: ⚡ MEDIUM
A13: Pacific Linehaul | B13: 2 | C13: 103 | D13: 0.0194 | E13: ⚡ MEDIUM
A14: Atlantic Freightways | B14: 2 | C14: 72 | D14: 0.0278 | E14: ⚠️ HIGH
A15: Cascade Cargo | B15: 1 | C15: 77 | D15: 0.013 | E15: ⚡ MEDIUM
A16: Keystone Freight | B16: 1 | C16: 71 | D16: 0.0141 | E16: ⚡ MEDIUM
A17: Lone Star Transport | B17: 1 | C17: 101 | D17: 0.0099 | E17: ✓ LOW
A19: SEVERE DELAYS BY TRUCK TYPE
A20: Truck Type | B20: Severe Count | C20: Total Shipments | D20: % Severe | E20: Risk Level
A21: Intermodal | B21: 2 | C21: 100 | D21: 0.02 | E21: ⚡ MEDIUM
A22: Dry Van | B22: 8 | C22: 488 | D22: 0.0164 | E22: ⚡ MEDIUM
A23: Reefer | B23: 2 | C23: 235 | D23: 0.0085 | E23: ✓ LOW
A25: SEVERE DELAYS BY LANE DISTANCE
A26: Lane Distance | B26: Severe Count | C26: Total Shipments | D26: % Severe | E26: Risk Level
A27: 501-1000 | B27: 2 | C27: 102 | D27: 0.0196 | E27: ⚡ MEDIUM
A28: 301-500 | B28: 3 | C28: 233 | D28: 0.0129 | E28: ⚡ MEDIUM
A29: 101-300 | B29: 6 | C29: 494 | D29: 0.0121 | E29: ⚡ MEDIUM
A30: 0-100 | B30: 1 | C30: 171 | D30: 0.0058 | E30: ✓ LOW
A32: SEVERE DELAYS BY REGION
A33: Region | B33: Severe Count | C33: Total Shipments | D33: % Severe | E33: Risk Level
A34: West | B34: 4 | C34: 243 | D34: 0.0165 | E34: ⚡ MEDIUM
A35: Northeast | B35: 3 | C35: 201 | D35: 0.0149 | E35: ⚡ MEDIUM
A36: South | B36: 4 | C36: 309 | D36: 0.0129 | E36: ⚡ MEDIUM
A37: Midwest | B37: 1 | C37: 247 | D37: 0.004 | E37: ✓ LOW
A39: SEVERE DELAYS BY REASON
A40: Delay Reason | B40: Count | C40: % of Severe Delays
A41: weather | B41: 6 | C41: 0.5
A42: mechanical | B42: 3 | C42: 0.25
A43: detention | B43: 2 | C43: 0.167
A44: traffic | B44: 1 | C44: 0.083
A46: KEY FINDINGS & TRENDS
A48: 🔴 CARRIER: Blue Ridge Logistics leads with 3 severe delays (1.2% rate)
...

Sheet RegressionAnalysis
A1: REGRESSION & CORRELATION ANALYSIS - DELAY MINUTES
A3: PART 1: CORRELATION MATRIX (Numeric Variables vs Delay Minutes)
A5: Variable | B5: Correlation (r) | C5: R-Squared (r²) | D5: Interpretation | E5: Direction | F5: Strength
A6: Distance Miles | B6: =CORREL(fact_orders_1000[distance_miles],fact_orders_1000[delay_minutes]) -> 0.02145695 | C6: =B6^2 -> 0.00046040069 | D6: =IF(ABS(B6)>0.5,"Strong",IF(ABS(B6)>0.3,"Moderate","Weak")) -> Weak | E6: =IF(B6>0,"Positive ↑","Negative ↓") -> Positive ↑ | F6: =ABS(B6) -> 0.02145695
A7: Traffic Index | B7: =CORREL(fact_orders_1000[traffic_index],fact_orders_1000[delay_minutes]) -> 0.069512653 | C7: =B7^2 -> 0.0048320089 | D7: =IF(ABS(B7)>0.5,"Strong",IF(ABS(B7)>0.3,"Moderate","Weak")) -> Weak | E7: =IF(B7>0,"Positive ↑","Negative ↓") -> Positive ↑ | F7: =ABS(B7) -> 0.069512653
A8: Weather Severity | B8: =CORREL(fact_orders_1000[weather_severity_index],fact_orders_1000[delay_minutes]) -> 0.31130427 | C8: =B8^2 -> 0.096910351 | D8: =IF(ABS(B8)>0.5,"Strong",IF(ABS(B8)>0.3,"Moderate","Weak")) -> Moderate | E8: =IF(B8>0,"Positive ↑","Negative ↓") -> Positive ↑ | F8: =ABS(B8) -> 0.31130427
A9: Detention Minutes | B9: =CORREL(fact_orders_1000[detention_minutes],fact_orders_1000[delay_minutes]) -> 0.53507289 | C9: =B9^2 -> 0.28630299 | D9: =IF(ABS(B9)>0.5,"Strong",IF(ABS(B9)>0.3,"Moderate","Weak")) -> Strong | E9: =IF(B9>0,"Positive ↑","Negative ↓") -> Positive ↑ | F9: =ABS(B9) -> 0.53507289
A10: Mechanical Flag | B10: =CORREL(fact_orders_1000[mechanical_flag],fact_orders_1000[delay_minutes]) -> 0.35158751 | C10: =B10^2 -> 0.12361378 | D10: =IF(ABS(B10)>0.5,"Strong",IF(ABS(B10)>0.3,"Moderate","Weak")) -> Moderate | E10: =IF(B10>0,"Positive ↑","Negative ↓") -> Positive ↑ | F10: =ABS(B10) -> 0.35158751
A11: Utilization Rate | B11: =CORREL(fact_orders_1000[utilization_rate],fact_orders_1000[delay_minutes]) -> 0.0032605932 | C11: =B11^2 -> 1.0631468e-05 | D11: =IF(ABS(B11)>0.5,"Strong",IF(ABS(B11)>0.3,"Moderate","Weak")) -> Weak | E11: =IF(B11>0,"Positive ↑","Negative ↓") -> Positive ↑ | F11: =ABS(B11) -> 0.0032605932
A12: Load Factor | B12: =CORREL(fact_orders_1000[load_factor],fact_orders_1000[delay_minutes]) -> -0.0054241531 | C12: =B12^2 -> 2.9421437e-05 | D12: =IF(ABS(B12)>0.5,"Strong",IF(ABS(B12)>0.3,"Moderate","Weak")) -> Weak | E12: =IF(B12>0,"Positive ↑","Negative ↓") -> Negative ↓ | F12: =ABS(B12) -> 0.0054241531
A13: Total Miles | B13: =CORREL(fact_orders_1000[total_miles],fact_orders_1000[delay_minutes]) -> 0.022335741 | C13: =B13^2 -> 0.0004988853 | D13: =IF(ABS(B13)>0.5,"Strong",IF(ABS(B13)>0.3,"Moderate","Weak")) -> Weak | E13: =IF(B13>0,"Positive ↑","Negative ↓") -> Positive ↑ | F13: =ABS(B13) -> 0.022335741
A14: Maintenance Cost | B14: =CORREL(fact_orders_1000[maintenance_cost_total],fact_orders_1000[delay_minutes]) -> 0.28833957 | C14: =B14^2 -> 0.083139709 | D14: =IF(ABS(B14)>0.5,"Strong",IF(ABS(B14)>0.3,"Moderate","Weak")) -> Weak | E14: =IF(B14>0,"Positive ↑","Negative ↓") -> Positive ↑ | F14: =ABS(B14) -> 0.28833957
A15: Insurance Risk Score | B15: =CORREL(fact_orders_1000[insurance_risk_score],fact_orders_1000[delay_minutes]) -> -0.027179113 | C15: =B15^2 -> 0.00073870419 | D15: =IF(ABS(B15)>0.5,"Strong",IF(ABS(B15)>0.3,"Moderate","Weak")) -> Weak | E15: =IF(B15>0,"Positive ↑","Negative ↓") -> Negative ↓ | F15: =ABS(B15) -> 0.027179113
A17: PART 2: LINEAR REGRESSION ANALYSIS
A19: Regression: Delay ~ Detention Minutes
A20: Intercept (a) | B20: =INTERCEPT(fact_orders_1000[delay_minutes],fact_orders_1000[detention_minutes]) -> -6.7921932
A21: Slope (b) | B21: =SLOPE(fact_orders_1000[delay_minutes],fact_orders_1000[detention_minutes]) -> 0.79641808
A22: R-Squared | B22: =RSQ(fact_orders_1000[delay_minutes],fact_orders_1000[detention_minutes]) -> 0.28630299
A23: Std Error | B23: =STEYX(fact_orders_1000[delay_minutes],fact_orders_1000[detention_minutes]) -> 67.542835
A25: Regression: Delay ~ Mechanical Flag
A26: Intercept (a) | B26: =INTERCEPT(fact_orders_1000[delay_minutes],fact_orders_1000[mechanical_flag]) -> 4.4703518
A27: Slope (b) | B27: =SLOPE(fact_orders_1000[delay_minutes],fact_orders_1000[mechanical_flag]) -> 398.12965
A28: R-Squared | B28: =RSQ(fact_orders_1000[delay_minutes],fact_orders_1000[mechanical_flag]) -> 0.12361378
A29: Std Error | B29: =STEYX(fact_orders_1000[delay_minutes],fact_orders_1000[mechanical_flag]) -> 74.846262
A31: Regression: Delay ~ Weather Severity
A32: Intercept (a) | B32: =INTERCEPT(fact_orders_1000[delay_minutes],fact_orders_1000[weather_severity_index]) -> 0.27214937
A33: Slope (b) | B33: =SLOPE(fact_orders_1000[delay_minutes],fact_orders_1000[weather_severity_index]) -> 42.799797
A34: R-Squared | B34: =RSQ(fact_orders_1000[delay_minutes],fact_orders_1000[weather_severity_index]) -> 0.096910351
A35: Std Error | B35: =STEYX(fact_orders_1000[delay_minutes],fact_orders_1000[weather_severity_index]) -> 75.977987
A37: PART 3: SEVERE vs NON-SEVERE DELAYS COMPARISON
A39: Variable | B39: Avg (Severe >300) | C39: Avg (Normal ≤300) | D39: Difference | E39: % Higher
A40: Distance Miles | B40: =AVERAGEIF(fact_orders_1000[delay_minutes],">300",fact_orders_1000[distance_miles]) -> 349.25 | C40: =AVERAGEIF(fact_orders_1000[delay_minutes],"<=300",fact_orders_1000[distance_miles]) -> 288.34109 | D40: =B40-C40 -> 60.908907 | E40: =IF(C40=0,0,(B40-C40)/C40) -> 0.21123908
A41: Traffic Index | B41: =AVERAGEIF(fact_orders_1000[delay_minutes],">300",fact_orders_1000[traffic_index]) -> 48.45 | C41: =AVERAGEIF(fact_orders_1000[delay_minutes],"<=300",fact_orders_1000[traffic_index]) -> 50.57419 | D41: =B41-C41 -> -2.1241903 | E41: =IF(C41=0,0,(B41-C41)/C41) -> -0.042001469
A42: Weather Severity | B42: =AVERAGEIF(fact_orders_1000[delay_minutes],">300",fact_orders_1000[weather_severity_index]) -> 1.6583333 | C42: =AVERAGEIF(fact_orders_1000[delay_minutes],"<=300",fact_orders_1000[weather_severity_index]) -> 0.12621457 | D42: =B42-C42 -> 1.5321188 | E42: =IF(C42=0,0,(B42-C42)/C42) -> 12.139
A43: Detention Minutes | B43: =AVERAGEIF(fact_orders_1000[delay_minutes],">300",fact_orders_1000[detention_minutes]) -> 46.083333 | C43: =AVERAGEIF(fact_orders_1000[delay_minutes],"<=300",fact_orders_1000[detention_minutes]) -> 16.283401 | D43: =B43-C43 -> 29.799933 | E43: =IF(C43=0,0,(B43-C43)/C43) -> 1.8300804
A44: Mechanical Flag | B44: =AVERAGEIF(fact_orders_1000[delay_minutes],">300",fact_orders_1000[mechanical_flag]) -> 0.25 | C44: =AVERAGEIF(fact_orders_1000[delay_minutes],"<=300",fact_orders_1000[mechanical_flag]) -> 0.0020242915 | D44: =B44-C44 -> 0.24797571 | E44: =IF(C44=0,0,(B44-C44)/C44) -> 122.5
A45: Maintenance Cost | B45: =AVERAGEIF(fact_orders_1000[delay_minutes],">300",fact_orders_1000[maintenance_cost_total]) -> 221.38417 | C45: =AVERAGEIF(fact_orders_1000[delay_minutes],"<=300",fact_orders_1000[maintenance_cost_total]) -> 55.72833 | D45: =B45-C45 -> 165.65584 | E45: =IF(C45=0,0,(B45-C45)/C45) -> 2.9725606
A46: Insurance Risk | B46: =AVERAGEIF(fact_orders_1000[delay_minutes],">300",fact_orders_1000[insurance_risk_score]) -> 20.566667 | C46: =AVERAGEIF(fact_orders_1000[delay_minutes],"<=300",fact_orders_1000[insurance_risk_score]) -> 18.635223 | D46: =B46-C46 -> 1.931444 | E46: =IF(C46=0,0,(B46-C46)/C46) -> 0.1036448
A48: PART 4: INTERPRETATION GUIDE
A50: 📊 CORRELATION GUIDE:
...

Sheet RPM_Correlation
A1: CORRELATION ANALYSIS: COST PER MILE (RPM) - Finding Strong Correlations (>0.7)
A3: PART 1: CORRELATION MATRIX (Variables vs Cost Per Mile)
A5: Variable | B5: Correlation (r) | C5: R² (Explained Variance) | D5: Strength | E5: Meets >0.7? | F5: Impact on RPM
A6: Variable Cost Per Mile | B6: =CORREL(fact_orders_1000!AU2:AU1002,fact_orders_1000!AV2:AV1002) -> 0.72995772 | C6: =B6^2 -> 0.53283827 | D6: =IF(ABS(B6)>=0.7,"🔴 STRONG",IF(ABS(B6)>=0.3,"🟠 Moderate","🟢 Weak")) -> 🔴 STRONG | E6: =IF(ABS(B6)>=0.7,"✅ YES","❌ No") -> ✅ YES | F6: =IF(B6>0,"↑ Higher = Higher RPM","↓ Higher = Lower RPM") -> ↑ Higher = Higher RPM
A7: Fuel Cost Total | B7: =CORREL(fact_orders_1000!AU2:AU1002,fact_orders_1000!AW2:AW1002) -> 0.11422494 | C7: =B7^2 -> 0.013047336 | D7: =IF(ABS(B7)>=0.7,"🔴 STRONG",IF(ABS(B7)>=0.3,"🟠 Moderate","🟢 Weak")) -> 🟢 Weak | E7: =IF(ABS(B7)>=0.7,"✅ YES","❌ No") -> ❌ No | F7: =IF(B7>0,"↑ Higher = Higher RPM","↓ Higher = Lower RPM") -> ↑ Higher = Higher RPM
A8: Maintenance Cost Total | B8: =CORREL(fact_orders_1000!AU2:AU1002,fact_orders_1000!AX2:AX1002) -> 0.025345029 | C8: =B8^2 -> 0.00064237051 | D8: =IF(ABS(B8)>=0.7,"🔴 STRONG",IF(ABS(B8)>=0.3,"🟠 Moderate","🟢 Weak")) -> 🟢 Weak | E8: =IF(ABS(B8)>=0.7,"✅ YES","❌ No") -> ❌ No | F8: =IF(B8>0,"↑ Higher = Higher RPM","↓ Higher = Lower RPM") -> ↑ Higher = Higher RPM
A9: Driver Pay Total | B9: =CORREL(fact_orders_1000!AU2:AU1002,fact_orders_1000!AY2:AY1002) -> 0.1146758 | C9: =B9^2 -> 0.013150539 | D9: =IF(ABS(B9)>=0.7,"🔴 STRONG",IF(ABS(B9)>=0.3,"🟠 Moderate","🟢 Weak")) -> 🟢 Weak | E9: =IF(ABS(B9)>=0.7,"✅ YES","❌ No") -> ❌ No | F9: =IF(B9>0,"↑ Higher = Higher RPM","↓ Higher = Lower RPM") -> ↑ Higher = Higher RPM
A10: Distance Miles | B10: =CORREL(fact_orders_1000!AU2:AU1002,fact_orders_1000!U2:U1002) -> 0.11326436 | C10: =B10^2 -> 0.012828815 | D10: =IF(ABS(B10)>=0.7,"🔴 STRONG",IF(ABS(B10)>=0.3,"🟠 Moderate","🟢 Weak")) -> 🟢 Weak | E10: =IF(ABS(B10)>=0.7,"✅ YES","❌ No") -> ❌ No | F10: =IF(B10>0,"↑ Higher = Higher RPM","↓ Higher = Lower RPM") -> ↑ Higher = Higher RPM
A11: Total Miles | B11: =CORREL(fact_orders_1000!AU2:AU1002,fact_orders_1000!Y2:Y1002) -> 0.11596771 | C11: =B11^2 -> 0.013448509 | D11: =IF(ABS(B11)>=0.7,"🔴 STRONG",IF(ABS(B11)>=0.3,"🟠 Moderate","🟢 Weak")) -> 🟢 Weak | E11: =IF(ABS(B11)>=0.7,"✅ YES","❌ No") -> ❌ No | F11: =IF(B11>0,"↑ Higher = Higher RPM","↓ Higher = Lower RPM") -> ↑ Higher = Higher RPM
A12: Loaded Miles | B12: =CORREL(fact_orders_1000!AU2:AU1002,fact_orders_1000!X2:X1002) -> 0.11402896 | C12: =B12^2 -> 0.013002603 | D12: =IF(ABS(B12)>=0.7,"🔴 STRONG",IF(ABS(B12)>=0.3,"🟠 Moderate","🟢 Weak")) -> 🟢 Weak | E12: =IF(ABS(B12)>=0.7,"✅ YES","❌ No") -> ❌ No | F12: =IF(B12>0,"↑ Higher = Higher RPM","↓ Higher = Lower RPM") -> ↑ Higher = Higher RPM
A13: Empty Miles | B13: =CORREL(fact_orders_1000!AU2:AU1002,fact_orders_1000!V2:V1002) -> 0.070521686 | C13: =B13^2 -> 0.0049733082 | D13: =IF(ABS(B13)>=0.7,"🔴 STRONG",IF(ABS(B13)>=0.3,"🟠 Moderate","🟢 Weak")) -> 🟢 Weak | E13: =IF(ABS(B13)>=0.7,"✅ YES","❌ No") -> ❌ No | F13: =IF(B13>0,"↑ Higher = Higher RPM","↓ Higher = Lower RPM") -> ↑ Higher = Higher RPM
A14: Deadhead Miles | B14: =CORREL(fact_orders_1000!AU2:AU1002,fact_orders_1000!W2:W1002) -> -0.024814487 | C14: =B14^2 -> 0.00061575875 | D14: =IF(ABS(B14)>=0.7,"🔴 STRONG",IF(ABS(B14)>=0.3,"🟠 Moderate","🟢 Weak")) -> 🟢 Weak | E14: =IF(ABS(B14)>=0.7,"✅ YES","❌ No") -> ❌ No | F14: =IF(B14>0,"↑ Higher = Higher RPM","↓ Higher = Lower RPM") -> ↓ Higher = Lower RPM
A15: Shipment Value USD | B15: =CORREL(fact_orders_1000!AU2:AU1002,fact_orders_1000!AL2:AL1002) -> -0.023009145 | C15: =B15^2 -> 0.00052942075 | D15: =IF(ABS(B15)>=0.7,"🔴 STRONG",IF(ABS(B15)>=0.3,"🟠 Moderate","🟢 Weak")) -> 🟢 Weak | E15: =IF(ABS(B15)>=0.7,"✅ YES","❌ No") -> ❌ No | F15: =IF(B15>0,"↑ Higher = Higher RPM","↓ Higher = Lower RPM") -> ↓ Higher = Lower RPM
A16: Delay Minutes | B16: =CORREL(fact_orders_1000!AU2:AU1002,fact_orders_1000!AE2:AE1002) -> -0.0036328486 | C16: =B16^2 -> 1.3197589e-05 | D16: =IF(ABS(B16)>=0.7,"🔴 STRONG",IF(ABS(B16)>=0.3,"🟠 Moderate","🟢 Weak")) -> 🟢 Weak | E16: =IF(ABS(B16)>=0.7,"✅ YES","❌ No") -> ❌ No | F16: =IF(B16>0,"↑ Higher = Higher RPM","↓ Higher = Lower RPM") -> ↓ Higher = Lower RPM
A17: Detention Minutes | B17: =CORREL(fact_orders_1000!AU2:AU1002,fact_orders_1000!AF2:AF1002) -> -0.019280617 | C17: =B17^2 -> 0.00037174219 | D17: =IF(ABS(B17)>=0.7,"🔴 STRONG",IF(ABS(B17)>=0.3,"🟠 Moderate","🟢 Weak")) -> 🟢 Weak | E17: =IF(ABS(B17)>=0.7,"✅ YES","❌ No") -> ❌ No | F17: =IF(B17>0,"↑ Higher = Higher RPM","↓ Higher = Lower RPM") -> ↓ Higher = Lower RPM
A18: Weather Severity | B18: =CORREL(fact_orders_1000!AU2:AU1002,fact_orders_1000!AG2:AG1002) -> 0.042644051 | C18: =B18^2 -> 0.001818515 | D18: =IF(ABS(B18)>=0.7,"🔴 STRONG",IF(ABS(B18)>=0.3,"🟠 Moderate","🟢 Weak")) -> 🟢 Weak | E18: =IF(ABS(B18)>=0.7,"✅ YES","❌ No") -> ❌ No | F18: =IF(B18>0,"↑ Higher = Higher RPM","↓ Higher = Lower RPM") -> ↑ Higher = Higher RPM
A19: Traffic Index | B19: =CORREL(fact_orders_1000!AU2:AU1002,fact_orders_1000!AH2:AH1002) -> 0.025284431 | C19: =B19^2 -> 0.00063930247 | D19: =IF(ABS(B19)>=0.7,"🔴 STRONG",IF(ABS(B19)>=0.3,"🟠 Moderate","🟢 Weak")) -> 🟢 Weak | E19: =IF(ABS(B19)>=0.7,"✅ YES","❌ No") -> ❌ No | F19: =IF(B19>0,"↑ Higher = Higher RPM","↓ Higher = Lower RPM") -> ↑ Higher = Higher RPM
A20: Utilization Rate | B20: =CORREL(fact_orders_1000!AU2:AU1002,fact_orders_1000!AJ2:AJ1002) -> 0.012910874 | C20: =B20^2 -> 0.00016669067 | D20: =IF(ABS(B20)>=0.7,"🔴 STRONG",IF(ABS(B20)>=0.3,"🟠 Moderate","🟢 Weak")) -> 🟢 Weak | E20: =IF(ABS(B20)>=0.7,"✅ YES","❌ No") -> ❌ No | F20: =IF(B20>0,"↑ Higher = Higher RPM","↓ Higher = Lower RPM") -> ↑ Higher = Higher RPM
A21: Load Factor | B21: =CORREL(fact_orders_1000!AU2:AU1002,fact_orders_1000!AK2:AK1002) -> 0.063610923 | C21: =B21^2 -> 0.0040463495 | D21: =IF(ABS(B21)>=0.7,"🔴 STRONG",IF(ABS(B21)>=0.3,"🟠 Moderate","🟢 Weak")) -> 🟢 Weak | E21: =IF(ABS(B21)>=0.7,"✅ YES","❌ No") -> ❌ No | F21: =IF(B21>0,"↑ Higher = Higher RPM","↓ Higher = Lower RPM") -> ↑ Higher = Higher RPM
A22: Insurance Risk Score | B22: =CORREL(fact_orders_1000!AU2:AU1002,fact_orders_1000!AZ2:AZ1002) -> 0.043186845 | C22: =B22^2 -> 0.0018651036 | D22: =IF(ABS(B22)>=0.7,"🔴 STRONG",IF(ABS(B22)>=0.3,"🟠 Moderate","🟢 Weak")) -> 🟢 Weak | E22: =IF(ABS(B22)>=0.7,"✅ YES","❌ No") -> ❌ No | F22: =IF(B22>0,"↑ Higher = Higher RPM","↓ Higher = Lower RPM") -> ↑ Higher = Higher RPM
A23: Maintenance Risk Score | B23: =CORREL(fact_orders_1000!AU2:AU1002,fact_orders_1000!BA2:BA1002) -> -0.011110012 | C23: =B23^2 -> 0.00012343236 | D23: =IF(ABS(B23)>=0.7,"🔴 STRONG",IF(ABS(B23)>=0.3,"🟠 Moderate","🟢 Weak")) -> 🟢 Weak | E23: =IF(ABS(B23)>=0.7,"✅ YES","❌ No") -> ❌ No | F23: =IF(B23>0,"↑ Higher = Higher RPM","↓ Higher = Lower RPM") -> ↓ Higher = Lower RPM
A26: PART 2: STRONG CORRELATIONS SUMMARY (|r| > 0.7)
A28: Variables with correlation > 0.7 indicate strong predictors of Cost Per Mile:
A30: Count of Strong Correlations (>0.7): | B30: =COUNTIF(E6:E23,"✅ YES") -> 1
A33: PART 3: REGRESSION EQUATIONS FOR TOP PREDICTORS
A35: Regression: Cost_Per_Mile ~ Variable_Cost_Per_Mile
A36: Intercept (a) | B36: =INTERCEPT(fact_orders_1000!AU2:AU1002,fact_orders_1000!AV2:AV1002) -> 1.0727742
A37: Slope (b) | B37: =SLOPE(fact_orders_1000!AU2:AU1002,fact_orders_1000!AV2:AV1002) -> 0.7591332
A38: R-Squared | B38: =RSQ(fact_orders_1000!AU2:AU1002,fact_orders_1000!AV2:AV1002) -> 0.53283827
A39: Equation | B39: ="RPM = "&ROUND(B36,2)&" + "&ROUND(B37,2)&" × Variable_CPM" -> RPM = 1.07 + 0.76 × Variable_CPM
A42: Regression: Cost_Per_Mile ~ Fuel_Cost_Total
A43: Intercept (a) | B43: =INTERCEPT(fact_orders_1000!AU2:AU1002,fact_orders_1000!AW2:AW1002) -> 2.2146173
A44: Slope (b) | B44: =SLOPE(fact_orders_1000!AU2:AU1002,fact_orders_1000!AW2:AW1002) -> 0.0001512424
A45: R-Squared | B45: =RSQ(fact_orders_1000!AU2:AU1002,fact_orders_1000!AW2:AW1002) -> 0.013047336
A46: Equation | B46: ="RPM = "&ROUND(B43,2)&" + "&ROUND(B44,4)&" × Fuel_Cost" -> RPM = 2.21 + 0.0002 × Fuel_Cost
A49: PART 4: BUSINESS IMPACT - What Drives Cost Per Mile?
A51: Category | B51: Avg RPM | C51: Count | D51: vs Overall Avg
A52: Overall Average RPM | B52: =AVERAGE(fact_orders_1000!AU2:AU1002) -> 2.25372 | C52: =COUNT(fact_orders_1000!AU2:AU1002) -> 1000 | D52: Baseline
A54: RPM by Truck Type:
A55: Dry Van | B55: =AVERAGEIF(fact_orders_1000!Z2:Z1002,"Dry Van",fact_orders_1000!AU2:AU1002) -> 2.1807172 | C55: =COUNTIF(fact_orders_1000!Z2:Z1002,"Dry Van") -> 488 | D55: =B55-B52 -> -0.073002787
...

Sheet OpCostAnalysis
A1: OPERATIONAL COST METRICS & REGRESSION ANALYSIS
A3: PART 1: KEY OPERATIONAL COST METRICS
A5: Metric | B5: Value | C5: Unit | D5: Interpretation
A6: Total Fuel Cost | B6: =SUM(fact_orders_1000[fuel_cost_total]) -> 258543.21 | C6: USD | D6: Total fuel expenditure
A7: Total Maintenance Cost | B7: =SUM(fact_orders_1000[maintenance_cost_total]) -> 57716.2 | C7: USD | D7: Total maintenance
A8: Total Driver Pay | B8: =SUM(fact_orders_1000[driver_pay_total]) -> 201195.05 | C8: USD | D8: Total driver comp
A9: Total Operating Cost | B9: =B6+B7+B8 -> 517454.46 | C9: USD | D9: Sum of all costs
A11: Average Cost Per Mile | B11: =AVERAGE(fact_orders_1000[cost_per_mile]) -> 2.25372 | C11: $/mile | D11: Avg CPM
A12: Average Variable CPM | B12: =AVERAGE(fact_orders_1000[variable_cost_per_mile]) -> 1.5552077 | C12: $/mile | D12: Avg Var CPM
A13: Avg Fuel Cost/Ship | B13: =AVERAGE(fact_orders_1000[fuel_cost_total]) -> 258.54321 | C13: USD | D13: Avg fuel/shipment
A14: Avg Maint Cost/Ship | B14: =AVERAGE(fact_orders_1000[maintenance_cost_total]) -> 57.7162 | C14: USD | D14: Avg maint/shipment
A15: Avg Driver Pay/Ship | B15: =AVERAGE(fact_orders_1000[driver_pay_total]) -> 201.19505 | C15: USD | D15: Avg pay/shipment
A17: Total Miles Operated | B17: =SUM(fact_orders_1000[total_miles]) -> 333652 | C17: miles | D17: Total distance
A18: Total Deadhead Miles | B18: =SUM(fact_orders_1000[deadhead_miles]) -> 19208.6 | C18: miles | D18: Empty miles
